Broker: amqp://guest:guest@localhost:5672//
Result Backend: redis://localhost:6379/0
 
 -------------- celery@dhcp-10-22-132-180.wlan.ntnu.no v5.4.0 (opalescent)
--- ***** ----- 
-- ******* ---- macOS-15.0.1-arm64-arm-64bit 2025-03-04 17:13:18
- *** --- * --- 
- ** ---------- [config]
- ** ---------- .> app:         multi_agent_system:0x10518f700
- ** ---------- .> transport:   amqp://guest:**@localhost:5672//
- ** ---------- .> results:     redis://localhost:6379/0
- *** --- * --- .> concurrency: 4 (prefork)
-- ******* ---- .> task events: OFF (enable -E to monitor tasks in this worker)
--- ***** ----- 
 -------------- [queues]
                .> character_design_queue exchange=character_design_queue(direct) key=character_design_queue
                .> plot_development_queue exchange=plot_development_queue(direct) key=plot_development_queue
                .> story_writing_queue exchange=story_writing_queue(direct) key=story_writing_queue
                .> world_building_queue exchange=world_building_queue(direct) key=world_building_queue

[tasks]
  . src.tasks.task_registry.generic_task

[2025-03-04 17:13:18,617: WARNING/MainProcess] /Users/adamds/.pyenv/versions/3.8.12/lib/python3.8/site-packages/celery/worker/consumer/consumer.py:508: CPendingDeprecationWarning: The broker_connection_retry configuration setting will no longer determine
whether broker connection retries are made during startup in Celery 6.0 and above.
If you wish to retain the existing behavior for retrying connections on startup,
you should set broker_connection_retry_on_startup to True.
  warnings.warn(

[2025-03-04 17:13:18,625: INFO/MainProcess] Connected to amqp://guest:**@127.0.0.1:5672//
[2025-03-04 17:13:18,625: WARNING/MainProcess] /Users/adamds/.pyenv/versions/3.8.12/lib/python3.8/site-packages/celery/worker/consumer/consumer.py:508: CPendingDeprecationWarning: The broker_connection_retry configuration setting will no longer determine
whether broker connection retries are made during startup in Celery 6.0 and above.
If you wish to retain the existing behavior for retrying connections on startup,
you should set broker_connection_retry_on_startup to True.
  warnings.warn(

[2025-03-04 17:13:18,629: INFO/MainProcess] mingle: searching for neighbors
[2025-03-04 17:13:19,652: INFO/MainProcess] mingle: all alone
[2025-03-04 17:13:19,697: WARNING/MainProcess] /Users/adamds/.pyenv/versions/3.8.12/lib/python3.8/site-packages/kombu/pidbox.py:72: UserWarning: A node named celery@dhcp-10-22-132-180.wlan.ntnu.no is already using this process mailbox!

Maybe you forgot to shutdown the other node or did not do so properly?
Or if you meant to start multiple nodes on the same host please make sure
you give each node a unique node name!

  warnings.warn(W_PIDBOX_IN_USE.format(node=self))

[2025-03-04 17:13:19,701: INFO/MainProcess] celery@dhcp-10-22-132-180.wlan.ntnu.no ready.

worker: Warm shutdown (MainProcess)
2025-03-04 17:13:22,976 - INFO - Flushed system logs to logs/system_log_20250304_171318.json
[2025-03-04 17:13:22,976: INFO/MainProcess] Flushed system logs to logs/system_log_20250304_171318.json
2025-03-04 17:13:22,977 - INFO - Flushed interaction logs to logs/interaction_log_20250304_171318.json
[2025-03-04 17:13:22,977: INFO/MainProcess] Flushed interaction logs to logs/interaction_log_20250304_171318.json
2025-03-04 17:13:22,977 - INFO - Flushed LiteLLM logs to logs/litellm_log_20250304_171318.json
[2025-03-04 17:13:22,977: INFO/MainProcess] Flushed LiteLLM logs to logs/litellm_log_20250304_171318.json
[2025-03-04 17:13:22,977: WARNING/MainProcess] Flushing GLOBAL_LOG_DATA: {'run_id': '20250304_171318', 'agents': {}}
[2025-03-04 17:13:22,978: WARNING/MainProcess] Flushed logs to logs/litellm_log_20250304_171318.json
